Workbook

Sheet Presentacion
A1: Nombre de la Actividad: | B1: Taller sobre los precios, la demanda potencial y el pronóstico de ventas.
A2: Nombre Estudiante: | B2: Estiven Andres Orozco Q

Sheet Punto1 - Precio de venta
A1: Concepto | B1: Propuesta inicial | C1: Alternativa A | D1: Alternativa B | E1: Alternativa C | F1: Alternativa D
A2: Unidades a vender | B2: 22450 | C2: 28900 | D2: 28800 | E2: 27500 | F2: 28400
A3: Costo unitario | B3: 15350 | C3: 14380 | D3: 14050 | E3: 15350 | F3: 14400
A4: Margen esperado por el inversionista | B4: 0.168 | C4: 0.168 | D4: 0.168 | E4: 0.168 | F4: 0.168
A5: Inflacion esperada | B5: 0.07 | C5: 0.07 | D5: 0.07 | E5: 0.07 | F5: 0.07
A6: Gastos fijos totales | B6: 30000000 | C6: 30000000 | D6: 20000000 | E6: 25000000 | F6: 21000000
A8: Gasto Unitario (Gastos fijos/Unidades) | B8: =B6/B2 -> 1336.3029 | C8: =C6/C2 -> 1038.0623 | D8: =D6/D2 -> 694.44444 | E8: =E6/E2 -> 909.09091 | F8: =F6/F2 -> 739.43662
A9: Precio de venta | B9: =(B3+B8)/(1-B5-B4) -> 21898.035 | C9: =(C3+C8)/(1-C5-C4) -> 20233.678 | D9: =(D3+D8)/(1-D5-D4) -> 19349.665 | E9: =(E3+E8)/(1-E5-E4) -> 21337.39 | F9: =(F3+F8)/(1-F5-F4) -> 19868.027
A13: Resultados del proyecto
A14: Ventas netas | B14: =B2*B9 -> 4.9161089e+08 | C14: =C2*C9 -> 5.8475328e+08 | D14: =D2*D9 -> 5.5727034e+08 | E14: =E2*E9 -> 5.8677822e+08 | F14: =F2*F9 -> 5.6425197e+08
A15: Costo de la mercancia vendida | B15: =-B2*B3 -> -344607500 | C15: =-C2*C3 -> -415582000 | D15: =-D2*D3 -> -404640000 | E15: =-E2*E3 -> -422125000 | F15: =-F2*F3 -> -408960000
A16: Utilidad bruta | B16: =B14+B15 -> 1.4700339e+08 | C16: =C14+C15 -> 1.6917128e+08 | D16: =D14+D15 -> 1.5263034e+08 | E16: =E14+E15 -> 1.6465322e+08 | F16: =F14+F15 -> 1.5529197e+08
A17: gastos | B17: =-B2*B8 -> -30000000 | C17: =-C2*C8 -> -30000000 | D17: =-D2*D8 -> -20000000 | E17: =-E2*E8 -> -25000000 | F17: =-F2*F8 -> -21000000
A18: inflacion | B18: =-B14*B5 -> -34412762 | C18: =-C14*C5 -> -40932730 | D18: =-D14*D5 -> -39008924 | E18: =-E14*E5 -> -41074475 | F18: =-F14*F5 -> -39497638
A19: Utilidad neta | B19: =B16+B17+B18 -> 82590630 | C19: =C16+C17+C18 -> 98238551 | D19: =D16+D17+D18 -> 93621417 | E19: =E16+E17+E18 -> 98578740 | F19: =F16+F17+F18 -> 94794331
A21: Margen neto | B21: =B19/B14 -> 0.168 | C21: =C19/C14 -> 0.168 | D21: =D19/D14 -> 0.168 | E21: =E19/E14 -> 0.168 | F21: =F19/F14 -> 0.168

Sheet Punto 2 - pronostico de ventas
A1: PARAMETROS DEL PRONOSTICO
A2: Ventas base cada mes 1er trimestre 2021 ($) | B2: 60950000
A3: 2do trimestre: variacion vs trim. anterior | B3: 0.078
A4: 3er trimestre: variacion vs trim. anterior | B4: -0.065
A5: Octubre y noviembre: variacion vs trim. anterior | B5: 0.0845
A6: Diciembre: variacion vs noviembre | B6: 0.1138
A7: Inicio 2022: variacion vs diciembre 2021 | B7: 0.0665
A8: Inicio 2023: variacion vs diciembre 2022 | B8: -0.0935
A9: Inicio 2024: variacion vs noviembre 2023 | B9: -0.1168
A10: Inicio 2025: variacion vs diciembre 2024 | B10: 0.0595
A13: MES | B13: 2021 Proyeccion | C13: 2021 Acumulado | D13: 2022 Proyeccion | E13: 2022 Acumulado | F13: 2023 Proyeccion | G13: 2023 Acumulado | H13: 2024 Proyeccion | I13: 2024 Acumulado | J13: 2025 Proyeccion | K13: 2025 Acumulado
A14: ENERO | B14: =$B$2 -> 60950000 | C14: =B14 -> 60950000 | D14: =B25*(1+$B$7) -> 79141032 | E14: =D14 -> 79141032 | F14: =D25*(1+$B$8) -> 87344721 | G14: =F14 -> 87344721 | H14: =F24*(1+$B$9) -> 84324864 | I14: =H14 -> 84324864 | J14: =H25*(1+$B$10) -> 1.0877366e+08 | K14: =J14 -> 1.0877366e+08
A15: FEBRERO | B15: =B14 -> 60950000 | C15: =C14+B15 -> 121900000 | D15: =D14 -> 79141032 | E15: =E14+D15 -> 1.5828206e+08 | F15: =F14 -> 87344721 | G15: =G14+F15 -> 1.7468944e+08 | H15: =H14 -> 84324864 | I15: =I14+H15 -> 1.6864973e+08 | J15: =J14 -> 1.0877366e+08 | K15: =K14+J15 -> 2.1754733e+08
A16: MARZO | B16: =B14 -> 60950000 | C16: =C15+B16 -> 182850000 | D16: =D14 -> 79141032 | E16: =E15+D16 -> 2.374231e+08 | F16: =F14 -> 87344721 | G16: =G15+F16 -> 2.6203416e+08 | H16: =H14 -> 84324864 | I16: =I15+H16 -> 2.5297459e+08 | J16: =J14 -> 1.0877366e+08 | K16: =K15+J16 -> 3.2632099e+08
A17: ABRIL | B17: =B16*(1+$B$3) -> 65704100 | C17: =C16+B17 -> 248554100 | D17: =D16*(1+$B$3) -> 85314033 | E17: =E16+D17 -> 3.2273713e+08 | F17: =F16*(1+$B$3) -> 94157609 | G17: =G16+F17 -> 3.5619177e+08 | H17: =H16*(1+$B$3) -> 90902203 | I17: =I16+H17 -> 3.438768e+08 | J17: =J16*(1+$B$3) -> 1.1725801e+08 | K17: =K16+J17 -> 4.43579e+08
A18: MAYO | B18: =B17 -> 65704100 | C18: =C17+B18 -> 314258200 | D18: =D17 -> 85314033 | E18: =E17+D18 -> 4.0805116e+08 | F18: =F17 -> 94157609 | G18: =G17+F18 -> 4.5034938e+08 | H18: =H17 -> 90902203 | I18: =I17+H18 -> 4.34779e+08 | J18: =J17 -> 1.1725801e+08 | K18: =K17+J18 -> 5.60837e+08
A19: JUNIO | B19: =B17 -> 65704100 | C19: =C18+B19 -> 379962300 | D19: =D17 -> 85314033 | E19: =E18+D19 -> 4.933652e+08 | F19: =F17 -> 94157609 | G19: =G18+F19 -> 5.4450699e+08 | H19: =H17 -> 90902203 | I19: =I18+H19 -> 5.256812e+08 | J19: =J17 -> 1.1725801e+08 | K19: =K18+J19 -> 6.7809501e+08
A20: JULIO | B20: =B19*(1+$B$4) -> 61433334 | C20: =C19+B20 -> 4.4139563e+08 | D20: =D19*(1+$B$4) -> 79768621 | E20: =E19+D20 -> 5.7313382e+08 | F20: =F19*(1+$B$4) -> 88037365 | G20: =G19+F20 -> 6.3254435e+08 | H20: =H19*(1+$B$4) -> 84993560 | I20: =I19+H20 -> 6.1067476e+08 | J20: =J19*(1+$B$4) -> 1.0963624e+08 | K20: =K19+J20 -> 7.8773125e+08
A21: AGOSTO | B21: =B20 -> 61433334 | C21: =C20+B21 -> 502828967 | D21: =D20 -> 79768621 | E21: =E20+D21 -> 6.5290244e+08 | F21: =F20 -> 88037365 | G21: =G20+F21 -> 7.2058172e+08 | H21: =H20 -> 84993560 | I21: =I20+H21 -> 6.9566832e+08 | J21: =J20 -> 1.0963624e+08 | K21: =K20+J21 -> 8.9736749e+08
A22: SEPTIEMBRE | B22: =B20 -> 61433334 | C22: =C21+B22 -> 5.642623e+08 | D22: =D20 -> 79768621 | E22: =E21+D22 -> 7.3267106e+08 | F22: =F20 -> 88037365 | G22: =G21+F22 -> 8.0861908e+08 | H22: =H20 -> 84993560 | I22: =I21+H22 -> 7.8066188e+08 | J22: =J20 -> 1.0963624e+08 | K22: =K21+J22 -> 1.0070037e+09
A23: OCTUBRE | B23: =B22*(1+$B$5) -> 66624450 | C23: =C22+B23 -> 6.3088675e+08 | D23: =D22*(1+$B$5) -> 86509069 | E23: =E22+D23 -> 8.1918013e+08 | F23: =F22*(1+$B$5) -> 95476522 | G23: =G22+F23 -> 9.0409561e+08 | H23: =H22*(1+$B$5) -> 92175516 | I23: =I22+H23 -> 8.728374e+08 | J23: =J22*(1+$B$5) -> 1.189005e+08 | K23: =K22+J23 -> 1.1259042e+09
A24: NOVIEMBRE | B24: =B23 -> 66624450 | C24: =C23+B24 -> 6.975112e+08 | D24: =D23 -> 86509069 | E24: =E23+D24 -> 9.056892e+08 | F24: =F23 -> 95476522 | G24: =G23+F24 -> 9.9957213e+08 | H24: =H23 -> 92175516 | I24: =I23+H24 -> 9.6501292e+08 | J24: =J23 -> 1.189005e+08 | K24: =K23+J24 -> 1.2448047e+09
A25: DICIEMBRE | B25: =B24*(1+$B$6) -> 74206313 | C25: =C24+B25 -> 7.7171751e+08 | D25: =D24*(1+$B$6) -> 96353801 | E25: =E24+D25 -> 1.002043e+09 | F25: =F24*(1+$B$6) -> 1.0634175e+08 | G25: =G24+F25 -> 1.1059139e+09 | H25: =H24*(1+$B$6) -> 1.0266509e+08 | I25: =I24+H25 -> 1.067678e+09 | J25: =J24*(1+$B$6) -> 1.3243138e+08 | K25: =K24+J25 -> 1.3772361e+09
A27: Total anual | B27: =SUM(B14:B25) -> 7.7171751e+08 | D27: =SUM(D14:D25) -> 1.002043e+09 | F27: =SUM(F14:F25) -> 1.1059139e+09 | H27: =SUM(H14:H25) -> 1.067678e+09 | J27: =SUM(J14:J25) -> 1.3772361e+09
A28: Pronostico de ventas total 2021-2025 | B28: =B27+D27+F27+H27+J27 -> 5.3245885e+09

Sheet Respuestas 
A1: Pregunta | B1: Respuesta
A2: 1.a
B3: El proyecto inicial, NO se puede ejecutar.
B4: =_xlfn.CONCAT(" Precio de venta = ",TEXT('Punto1 - Precio de venta'!B9,"$ #.##0,00")) -> Precio de venta = $ 21.898,04 | C4: NO cumple la condicion 1 ( < $21.400).
B5: =_xlfn.CONCAT(" Margen neto = ",TEXT('Punto1 - Precio de venta'!B21,"0,00%")) -> Margen neto = 16,80% | C5: Cumple la condicion 2 (>= 16,80%).
B6: =_xlfn.CONCAT(" Utilidad neta = ",TEXT('Punto1 - Precio de venta'!B19,"$ #.##0,00")) -> Utilidad neta = $ 82.590.629,92 | C6: Cumple la condicion 3 (>= $75.000.000).
B8: ALTERNATIVA A, se puede ejecutar.
B9: =_xlfn.CONCAT(" Precio de venta = ",TEXT('Punto1 - Precio de venta'!C9,"$ #.##0")) -> Precio de venta = $ 20.234 | C9: Cumple la condicion 1 ( < $21.400).
B10: =_xlfn.CONCAT(" Margen neto = ",TEXT('Punto1 - Precio de venta'!C21,"0,00%")) -> Margen neto = 16,80% | C10: Cumple la condicion 2 (>= 16,80%).
B11: =_xlfn.CONCAT(" Utilidad neta = ",TEXT('Punto1 - Precio de venta'!C19,"$ #.##0")) -> Utilidad neta = $ 98.238.551 | C11: Cumple la condicion 3 (>= $75.000.000).
B13: ALTERNATIVA B, se puede ejecutar.
B14: =_xlfn.CONCAT(" Precio de venta = ",TEXT('Punto1 - Precio de venta'!D9,"$ #.##0")) -> Precio de venta = $ 19.350 | C14: Cumple la condicion 1 ( < $21.400).
B15: =_xlfn.CONCAT(" Margen neto = ",TEXT('Punto1 - Precio de venta'!D21,"0,00%")) -> Margen neto = 16,80% | C15: Cumple la condicion 2 (>= 16,80%).
B16: =_xlfn.CONCAT(" Utilidad neta = ",TEXT('Punto1 - Precio de venta'!D19,"$ #.##0")) -> Utilidad neta = $ 93.621.417 | C16: Cumple la condicion 3 (>= $75.000.000).
B18: ALTERNATIVA C, se puede ejecutar.
B19: =_xlfn.CONCAT(" Precio de venta = ",TEXT('Punto1 - Precio de venta'!E9,"$ #.##0")) -> Precio de venta = $ 21.337 | C19: Cumple la condicion 1 ( < $21.400).
B20: =_xlfn.CONCAT(" Margen neto = ",TEXT('Punto1 - Precio de venta'!E21,"0,00%")) -> Margen neto = 16,80% | C20: Cumple la condicion 2 (>= 16,80%).
B21: =_xlfn.CONCAT(" Utilidad neta = ",TEXT('Punto1 - Precio de venta'!E19,"$ #.##0")) -> Utilidad neta = $ 98.578.740 | C21: Cumple la condicion 3 (>= $75.000.000).
B24: ALTERNATIVA D, se puede ejecutar.
B25: =_xlfn.CONCAT(" Precio de venta = ",TEXT('Punto1 - Precio de venta'!F9,"$ #.##0")) -> Precio de venta = $ 19.868 | C25: Cumple la condicion 1 ( < $21.400).
B26: =_xlfn.CONCAT(" Margen neto = ",TEXT('Punto1 - Precio de venta'!F21,"0,00%")) -> Margen neto = 16,80% | C26: Cumple la condicion 2 (>= 16,80%).
B27: =_xlfn.CONCAT(" Utilidad neta = ",TEXT('Punto1 - Precio de venta'!F19,"$ #.##0")) -> Utilidad neta = $ 94.794.331 | C27: Cumple la condicion 3 (>= $75.000.000).
A29: 1.b
B30: COMPARACION:
B31: Alternativa | C31: Precio de venta | D31: Utilidad neta | E31: Holgura precio
B32: A | C32: =TEXT('Punto1 - Precio de venta'!C$9,"$ #.##0") -> $ 20.234 | D32: =TEXT('Punto1 - Precio de venta'!C$19,"$ #.##0") -> $ 98.238.551 | E32: =(21400 - C32) / 21400 -> 0.054485981
B33: B | C33: =TEXT('Punto1 - Precio de venta'!D$9,"$ #.##0") -> $ 19.350 | D33: =TEXT('Punto1 - Precio de venta'!D$19,"$ #.##0") -> $ 93.621.417 | E33: =(21400 - C33) / 21400 -> 0.095794393
B34: C | C34: =TEXT('Punto1 - Precio de venta'!E$9,"$ #.##0") -> $ 21.337 | D34: =TEXT('Punto1 - Precio de venta'!E$19,"$ #.##0") -> $ 98.578.740 | E34: =(21400 - C34) / 21400 -> 0.0029439252
B35: D | C35: =TEXT('Punto1 - Precio de venta'!F$9,"$ #.##0") -> $ 19.868 | D35: =TEXT('Punto1 - Precio de venta'!F$19,"$ #.##0") -> $ 94.794.331 | E35: =(21400 - C35) / 21400 -> 0.071588785
B37: SELECCION: la mejor alternativa es la A.
B38: Las cuatro cumplen las 3 condiciones. Se elige A porque:
B39: - Entrega practicamente la mayor utilidad neta ($98,2 M): solo 0,3% por debajo de la C
B40: ($98,6 M) y muy por encima de B ($93,6 M) y D ($94,8 M).
B41: - Su precio queda holgado frente al tope (5,5%). La C, que da la utilidad mas alta,
B42: queda a solo $63 del limite: cualquier desviacion minima de costo/gasto la vuelve
B43: inviable. La A logra casi la misma utilidad sin ese riesgo.
B44: - Es la de implementacion mas simple: sube volumen y baja el costo unitario, sin
B45: recortar gastos fijos (B, C y D si los recortan).
B46: Nota: si el docente pondera solo 'mayor utilidad', la respuesta seria la C, con la
B47: salvedad de que su precio queda al limite de la condicion 1.
...
